<?xml version="1.0" encoding="UTF-8"?>
<robot name="anymal_instanceable">
  <joint name="LF_HAA" type="revolute">
    <origin xyz="0.2999 0.104 0. " rpy="2.6179938 0. 0. "/>
    <parent link="anymal"/>
    <child link="LF_HIP"/>
    <axis xyz="1. 0. 0."/>
    <limit lower="-9.424778" upper="9.424778" effort="0." velocity="125.6637061"/>
  </joint>
  <joint name="LF_HFE" type="revolute">
    <origin xyz="0.0599 -0.0725816 -0.041905 " rpy="3.1415927 0.5235988 -1.5707964"/>
    <parent link="LF_HIP"/>
    <child link="LF_THIGH"/>
    <axis xyz="1. 0. 0."/>
    <limit lower="-9.424778" upper="9.424778" effort="0." velocity="125.6637061"/>
  </joint>
  <joint name="LF_KFE" type="revolute">
    <origin xyz="0.1003 -0. -0.2849999" rpy="0. 0. 0."/>
    <parent link="LF_THIGH"/>
    <child link="LF_SHANK"/>
    <axis xyz="1. 0. 0."/>
    <limit lower="-9.424778" upper="9.424778" effort="0." velocity="125.6637061"/>
  </joint>
  <joint name="LH_HAA" type="revolute">
    <origin xyz="-0.2999 0.104 0. " rpy="-0.5235988 0.0000001 -0.0000001"/>
    <parent link="anymal"/>
    <child link="LH_HIP"/>
    <axis xyz="1. 0. 0."/>
    <limit lower="-9.424778" upper="9.424778" effort="0." velocity="125.6637061"/>
  </joint>
  <joint name="LH_HFE" type="revolute">
    <origin xyz="-0.0599 0.0725816 0.041905 " rpy="-0.0000001 -0.5235988 1.5707966"/>
    <parent link="LH_HIP"/>
    <child link="LH_THIGH"/>
    <axis xyz="1. 0. 0."/>
    <limit lower="-9.424778" upper="9.424778" effort="0." velocity="125.6637061"/>
  </joint>
  <joint name="LH_KFE" type="revolute">
    <origin xyz="0.1003 -0. -0.2849999" rpy="0. 0. 0."/>
    <parent link="LH_THIGH"/>
    <child link="LH_SHANK"/>
    <axis xyz="1. 0. 0."/>
    <limit lower="-9.424778" upper="9.424778" effort="0." velocity="125.6637061"/>
  </joint>
  <joint name="RF_HAA" type="revolute">
    <origin xyz="0.2999 -0.104 0. " rpy="-2.6179938 0. 0. "/>
    <parent link="anymal"/>
    <child link="RF_HIP"/>
    <axis xyz="1. 0. 0."/>
    <limit lower="-9.424778" upper="9.424778" effort="0." velocity="125.6637061"/>
  </joint>
  <joint name="RF_HFE" type="revolute">
    <origin xyz="0.0599 0.0725816 -0.041905 " rpy="0. -0.5235988 -1.5707964"/>
    <parent link="RF_HIP"/>
    <child link="RF_THIGH"/>
    <axis xyz="1. 0. 0."/>
    <limit lower="-9.424778" upper="9.424778" effort="0." velocity="125.6637061"/>
  </joint>
  <joint name="RF_KFE" type="revolute">
    <origin xyz="-0.1003 0. 0.2849999" rpy="0. 0. 0."/>
    <parent link="RF_THIGH"/>
    <child link="RF_SHANK"/>
    <axis xyz="1. 0. 0."/>
    <limit lower="-9.424778" upper="9.424778" effort="0." velocity="125.6637061"/>
  </joint>
  <joint name="RH_HAA" type="revolute">
    <origin xyz="-0.2999 -0.104 0. " rpy="0.5235988 0.0000001 -0. "/>
    <parent link="anymal"/>
    <child link="RH_HIP"/>
    <axis xyz="1. 0. 0."/>
    <limit lower="-9.424778" upper="9.424778" effort="0." velocity="125.6637061"/>
  </joint>
  <joint name="RH_HFE" type="revolute">
    <origin xyz="-0.0599 -0.0725816 0.041905 " rpy="3.1415925 0.5235988 1.5707965"/>
    <parent link="RH_HIP"/>
    <child link="RH_THIGH"/>
    <axis xyz="1. 0. 0."/>
    <limit lower="-9.424778" upper="9.424778" effort="0." velocity="125.6637061"/>
  </joint>
  <joint name="RH_KFE" type="revolute">
    <origin xyz="-0.1003 0. 0.2849999" rpy="0. 0. 0."/>
    <parent link="RH_THIGH"/>
    <child link="RH_SHANK"/>
    <axis xyz="1. 0. 0."/>
    <limit lower="-9.424778" upper="9.424778" effort="0." velocity="125.6637061"/>
  </joint>
  <link name="LF_HIP">
    <inertial>
      <origin xyz="0. 0. 0." rpy="0. 0. 0."/>
      <mass value="2.5120299"/>
      <inertia ixx="0." ixy="0." ixz="0." iyy="0." iyz="0." izz="0."/>
    </inertial>
    <visual>
      <origin xyz="0. 0. 0." rpy="-1.0471976 0. 0. "/>
      <geometry>
        <mesh filename="meshes/LF_HIP_visuals_mesh_0.obj" scale="1. 1. 1."/>
      </geometry>
    </visual>
    <visual>
      <origin xyz="0.0599 -0.0725816 -0.041905 " rpy="-1.5707964 0.5235989 -1.5707964"/>
      <geometry>
        <mesh filename="meshes/LF_HIP_visuals_mesh_1.obj" scale="1. 1. 1."/>
      </geometry>
    </visual>
  </link>
  <link name="LF_SHANK">
    <inertial>
      <origin xyz="0. 0. 0." rpy="0. 0. 0."/>
      <mass value="0.55505"/>
      <inertia ixx="0." ixy="0." ixz="0." iyy="0." iyz="0." izz="0."/>
    </inertial>
    <visual>
      <origin xyz="0. 0. 0." rpy="1.5707964 0. -1.5707964"/>
      <geometry>
        <mesh filename="meshes/LF_SHANK_visuals_mesh_0.obj" scale="1. 1. 1."/>
      </geometry>
    </visual>
    <visual>
      <origin xyz="0.01305 -0.08795 -0.3379699" rpy="1.5707964 -0. -2.3561945"/>
      <geometry>
        <mesh filename="meshes/LF_SHANK_visuals_mesh_1.obj" scale="1. 1. 1."/>
      </geometry>
    </visual>
    <visual>
      <origin xyz="0.01305 -0.08795 -0.3154702" rpy="0. 0. -0.0000003"/>
      <geometry>
        <sphere radius="0.03"/>
      </geometry>
    </visual>
    <collision>
      <origin xyz="0.01305 -0.08795 -0.3154702" rpy="0. 0. -0.0000003"/>
      <geometry>
        <sphere radius="0.03"/>
      </geometry>
    </collision>
  </link>
  <link name="LF_THIGH">
    <inertial>
      <origin xyz="0. 0. 0." rpy="0. 0. 0."/>
      <mass value="3.2732699"/>
      <inertia ixx="0." ixy="0." ixz="0." iyy="0." iyz="0." izz="0."/>
    </inertial>
    <visual>
      <origin xyz="0. 0. 0." rpy="1.5707964 0. -1.5707964"/>
      <geometry>
        <mesh filename="meshes/LF_THIGH_visuals_mesh_0.obj" scale="1. 1. 1."/>
      </geometry>
    </visual>
    <visual>
      <origin xyz="0.1003 -0. -0.2849999" rpy="1.5707963 0. 0. "/>
      <geometry>
        <mesh filename="meshes/LF_THIGH_visuals_mesh_1.obj" scale="1. 1. 1."/>
      </geometry>
    </visual>
    <visual>
      <origin xyz="0.0503 -0. -0.2849999" rpy="0. 1.5707961 0. "/>
      <geometry>
        <cylinder radius="0.066" length="0.18"/>
      </geometry>
    </visual>
    <collision>
      <origin xyz="0.0503 -0. -0.2849999" rpy="0. 1.5707961 0. "/>
      <geometry>
        <cylinder radius="0.066" length="0.18"/>
      </geometry>
    </collision>
  </link>
  <link name="LH_HIP">
    <inertial>
      <origin xyz="0. 0. 0." rpy="0. 0. 0."/>
      <mass value="2.5120299"/>
      <inertia ixx="0." ixy="0." ixz="0." iyy="0." iyz="0." izz="0."/>
    </inertial>
    <visual>
      <origin xyz="0. 0. 0." rpy="1.0471975 0. -3.1415927"/>
      <geometry>
        <mesh filename="meshes/LH_HIP_visuals_mesh_0.obj" scale="1. 1. 1."/>
      </geometry>
    </visual>
    <visual>
      <origin xyz="-0.0599 0.0725816 0.041905 " rpy="1.5707961 -0.5235988 1.5707966"/>
      <geometry>
        <mesh filename="meshes/LH_HIP_visuals_mesh_1.obj" scale="1. 1. 1."/>
      </geometry>
    </visual>
  </link>
  <link name="LH_SHANK">
    <inertial>
      <origin xyz="0. 0. 0." rpy="0. 0. 0."/>
      <mass value="0.55505"/>
      <inertia ixx="0." ixy="0." ixz="0." iyy="0." iyz="0." izz="0."/>
    </inertial>
    <visual>
      <origin xyz="0. 0. 0." rpy="1.5707964 -0. 1.5707961"/>
      <geometry>
        <mesh filename="meshes/LH_SHANK_visuals_mesh_0.obj" scale="1. 1. 1."/>
      </geometry>
    </visual>
    <visual>
      <origin xyz="0.01305 0.08795 -0.3379699" rpy="1.5707964 -0. 2.3561945"/>
      <geometry>
        <mesh filename="meshes/LH_SHANK_visuals_mesh_1.obj" scale="1. 1. 1."/>
      </geometry>
    </visual>
    <visual>
      <origin xyz="0.01305 0.08795 -0.31547" rpy="0. 0. -1.5707963"/>
      <geometry>
        <sphere radius="0.03"/>
      </geometry>
    </visual>
    <collision>
      <origin xyz="0.01305 0.08795 -0.31547" rpy="0. 0. -1.5707963"/>
      <geometry>
        <sphere radius="0.03"/>
      </geometry>
    </collision>
  </link>
  <link name="LH_THIGH">
    <inertial>
      <origin xyz="0. 0. 0." rpy="0. 0. 0."/>
      <mass value="3.2732699"/>
      <inertia ixx="0." ixy="0." ixz="0." iyy="0." iyz="0." izz="0."/>
    </inertial>
    <visual>
      <origin xyz="0. 0. 0." rpy="1.5707964 0. -1.5707964"/>
      <geometry>
        <mesh filename="meshes/LH_THIGH_visuals_mesh_0.obj" scale="1. 1. 1."/>
      </geometry>
    </visual>
    <visual>
      <origin xyz="0.1003 -0. -0.2849999" rpy="1.5707963 0. 0. "/>
      <geometry>
        <mesh filename="meshes/LH_THIGH_visuals_mesh_1.obj" scale="1. 1. 1."/>
      </geometry>
    </visual>
    <visual>
      <origin xyz="0.0503 -0. -0.2849999" rpy="0. 1.5707961 0. "/>
      <geometry>
        <cylinder radius="0.066" length="0.18"/>
      </geometry>
    </visual>
    <collision>
      <origin xyz="0.0503 -0. -0.2849999" rpy="0. 1.5707961 0. "/>
      <geometry>
        <cylinder radius="0.066" length="0.18"/>
      </geometry>
    </collision>
  </link>
  <link name="RF_HIP">
    <inertial>
      <origin xyz="0. 0. 0." rpy="0. 0. 0."/>
      <mass value="2.5120299"/>
      <inertia ixx="0." ixy="0." ixz="0." iyy="0." iyz="0." izz="0."/>
    </inertial>
    <visual>
      <origin xyz="0. 0. 0." rpy="-2.0943952 0. 0. "/>
      <geometry>
        <mesh filename="meshes/RF_HIP_visuals_mesh_0.obj" scale="1. 1. 1."/>
      </geometry>
    </visual>
    <visual>
      <origin xyz="0.0599 0.0725816 -0.041905 " rpy="-1.5707964 0.5235989 1.5707964"/>
      <geometry>
        <mesh filename="meshes/RF_HIP_visuals_mesh_1.obj" scale="1. 1. 1."/>
      </geometry>
    </visual>
  </link>
  <link name="RF_SHANK">
    <inertial>
      <origin xyz="0. 0. 0." rpy="0. 0. 0."/>
      <mass value="0.55505"/>
      <inertia ixx="0." ixy="0." ixz="0." iyy="0." iyz="0." izz="0."/>
    </inertial>
    <visual>
      <origin xyz="0. 0. 0." rpy="-1.5707964 0. 1.5707964"/>
      <geometry>
        <mesh filename="meshes/RF_SHANK_visuals_mesh_0.obj" scale="1. 1. 1."/>
      </geometry>
    </visual>
    <visual>
      <origin xyz="-0.01305 0.08795 0.3379699" rpy="-1.5707964 -0. 0.7853981"/>
      <geometry>
        <mesh filename="meshes/RF_SHANK_visuals_mesh_1.obj" scale="1. 1. 1."/>
      </geometry>
    </visual>
    <visual>
      <origin xyz="-0.01305 0.08795 0.31547" rpy="3.1415925 0. 1.5707964"/>
      <geometry>
        <sphere radius="0.03"/>
      </geometry>
    </visual>
    <collision>
      <origin xyz="-0.01305 0.08795 0.31547" rpy="3.1415925 0. 1.5707964"/>
      <geometry>
        <sphere radius="0.03"/>
      </geometry>
    </collision>
  </link>
  <link name="RF_THIGH">
    <inertial>
      <origin xyz="0. 0. 0." rpy="0. 0. 0."/>
      <mass value="3.2732699"/>
      <inertia ixx="0." ixy="0." ixz="0." iyy="0." iyz="0." izz="0."/>
    </inertial>
    <visual>
      <origin xyz="0. 0. 0." rpy="-1.5707963 0. -1.5707961"/>
      <geometry>
        <mesh filename="meshes/RF_THIGH_visuals_mesh_0.obj" scale="1. 1. 1."/>
      </geometry>
    </visual>
    <visual>
      <origin xyz="-0.1003 0. 0.2849999" rpy="-1.5707964 0.0000001 -3.1415927"/>
      <geometry>
        <mesh filename="meshes/RF_THIGH_visuals_mesh_1.obj" scale="1. 1. 1."/>
      </geometry>
    </visual>
    <visual>
      <origin xyz="-0.0503 0. 0.2849999" rpy="3.1415927 -1.570796 -3.1415927"/>
      <geometry>
        <cylinder radius="0.066" length="0.18"/>
      </geometry>
    </visual>
    <collision>
      <origin xyz="-0.0503 0. 0.2849999" rpy="3.1415927 -1.570796 -3.1415927"/>
      <geometry>
        <cylinder radius="0.066" length="0.18"/>
      </geometry>
    </collision>
  </link>
  <link name="RH_HIP">
    <inertial>
      <origin xyz="0. 0. 0." rpy="0. 0. 0."/>
      <mass value="2.5120299"/>
      <inertia ixx="0." ixy="0." ixz="0." iyy="0." iyz="0." izz="0."/>
    </inertial>
    <visual>
      <origin xyz="0. 0. 0." rpy="2.0943952 0.0000001 -3.1415927"/>
      <geometry>
        <mesh filename="meshes/RH_HIP_visuals_mesh_0.obj" scale="1. 1. 1."/>
      </geometry>
    </visual>
    <visual>
      <origin xyz="-0.0599 -0.0725816 0.041905 " rpy="1.5707964 -0.5235988 -1.5707961"/>
      <geometry>
        <mesh filename="meshes/RH_HIP_visuals_mesh_1.obj" scale="1. 1. 1."/>
      </geometry>
    </visual>
  </link>
  <link name="RH_SHANK">
    <inertial>
      <origin xyz="0. 0. 0." rpy="0. 0. 0."/>
      <mass value="0.55505"/>
      <inertia ixx="0." ixy="0." ixz="0." iyy="0." iyz="0." izz="0."/>
    </inertial>
    <visual>
      <origin xyz="0. 0. 0." rpy="-1.5707963 0. -1.5707961"/>
      <geometry>
        <mesh filename="meshes/RH_SHANK_visuals_mesh_0.obj" scale="1. 1. 1."/>
      </geometry>
    </visual>
    <visual>
      <origin xyz="-0.01305 -0.08795 0.3379699" rpy="-1.5707963 -0. -0.7853982"/>
      <geometry>
        <mesh filename="meshes/RH_SHANK_visuals_mesh_1.obj" scale="1. 1. 1."/>
      </geometry>
    </visual>
    <visual>
      <origin xyz="-0.01305 -0.08795 0.31547" rpy="3.1415925 0. 1.5707964"/>
      <geometry>
        <sphere radius="0.03"/>
      </geometry>
    </visual>
    <collision>
      <origin xyz="-0.01305 -0.08795 0.31547" rpy="3.1415925 0. 1.5707964"/>
      <geometry>
        <sphere radius="0.03"/>
      </geometry>
    </collision>
  </link>
  <link name="RH_THIGH">
    <inertial>
      <origin xyz="0. 0. 0." rpy="0. 0. 0."/>
      <mass value="3.2732699"/>
      <inertia ixx="0." ixy="0." ixz="0." iyy="0." iyz="0." izz="0."/>
    </inertial>
    <visual>
      <origin xyz="0. 0. 0." rpy="-1.5707963 0. -1.5707961"/>
      <geometry>
        <mesh filename="meshes/RH_THIGH_visuals_mesh_0.obj" scale="1. 1. 1."/>
      </geometry>
    </visual>
    <visual>
      <origin xyz="-0.1003 0. 0.2849999" rpy="-1.5707964 0.0000001 -3.1415927"/>
      <geometry>
        <mesh filename="meshes/RH_THIGH_visuals_mesh_1.obj" scale="1. 1. 1."/>
      </geometry>
    </visual>
    <visual>
      <origin xyz="-0.0503 0. 0.2849999" rpy="3.1415927 -1.570796 -3.1415927"/>
      <geometry>
        <cylinder radius="0.066" length="0.18"/>
      </geometry>
    </visual>
    <collision>
      <origin xyz="-0.0503 0. 0.2849999" rpy="3.1415927 -1.570796 -3.1415927"/>
      <geometry>
        <cylinder radius="0.066" length="0.18"/>
      </geometry>
    </collision>
  </link>
  <link name="anymal">
    <visual>
      <origin xyz="0. 0. 0." rpy="1.5707965 0. 0. "/>
      <geometry>
        <mesh filename="meshes/base_visuals_mesh_0.obj" scale="1. 1. 1."/>
      </geometry>
    </visual>
    <visual>
      <origin xyz="0.2999 0.104 0. " rpy="-2.0943952 0. 0. "/>
      <geometry>
        <mesh filename="meshes/base_visuals_mesh_1.obj" scale="1. 1. 1."/>
      </geometry>
    </visual>
    <visual>
      <origin xyz="-0.2999 0.104 0. " rpy="-1.0471975 0. 3.1415925"/>
      <geometry>
        <mesh filename="meshes/base_visuals_mesh_2.obj" scale="1. 1. 1."/>
      </geometry>
    </visual>
    <visual>
      <origin xyz="0.2999 -0.104 0. " rpy="-1.0471976 0. 0. "/>
      <geometry>
        <mesh filename="meshes/base_visuals_mesh_3.obj" scale="1. 1. 1."/>
      </geometry>
    </visual>
    <visual>
      <origin xyz="-0.2999 -0.104 0. " rpy="-2.0943952 0. 3.1415925"/>
      <geometry>
        <mesh filename="meshes/mesh_4.obj" scale="1. 1. 1."/>
      </geometry>
    </visual>
    <visual>
      <origin xyz="0. 0. 0." rpy="1.5707965 0. 0. "/>
      <geometry>
        <mesh filename="meshes/mesh_5.obj" scale="1. 1. 1."/>
      </geometry>
    </visual>
    <visual>
      <origin xyz="0. 0. 0." rpy="1.5707965 0. 0. "/>
      <geometry>
        <mesh filename="meshes/mesh_6.obj" scale="1. 1. 1."/>
      </geometry>
    </visual>
    <visual>
      <origin xyz="0.4145 0. 0. " rpy="1.5707965 0. 0. "/>
      <geometry>
        <mesh filename="meshes/mesh_7.obj" scale="1. 1. 1."/>
      </geometry>
    </visual>
    <visual>
      <origin xyz="0.513 0. 0.01497" rpy="1.5707965 0. 0. "/>
      <geometry>
        <mesh filename="meshes/mesh_8.obj" scale="1. 1. 1."/>
      </geometry>
    </visual>
    <visual>
      <origin xyz="0.46165 0. -0.0292 " rpy="1.5888251 0.4852504 -0. "/>
      <geometry>
        <mesh filename="meshes/mesh_9.obj" scale="1. 1. 1."/>
      </geometry>
    </visual>
    <visual>
      <origin xyz="-0.4145 0. 0. " rpy="1.5707964 0. -3.1415925"/>
      <geometry>
        <mesh filename="meshes/mesh_10.obj" scale="1. 1. 1."/>
      </geometry>
    </visual>
    <visual>
      <origin xyz="-0.513 -0. 0.01497" rpy="1.5707964 0. -3.1415925"/>
      <geometry>
        <mesh filename="meshes/mesh_11.obj" scale="1. 1. 1."/>
      </geometry>
    </visual>
    <visual>
      <origin xyz="-0.46165 -0. -0.0292 " rpy="1.5896485 0.5297861 -3.1415925"/>
      <geometry>
        <mesh filename="meshes/mesh_12.obj" scale="1. 1. 1."/>
      </geometry>
    </visual>
    <visual>
      <origin xyz="0. 0. 0." rpy="1.5707965 0. 0. "/>
      <geometry>
        <mesh filename="meshes/mesh_13.obj" scale="1. 1. 1."/>
      </geometry>
    </visual>
    <visual>
      <origin xyz="0.116 0. 0.073" rpy="1.5707965 0. 0. "/>
      <geometry>
        <mesh filename="meshes/mesh_14.obj" scale="1. 1. 1."/>
      </geometry>
    </visual>
    <visual>
      <origin xyz="0. 0.07646 0.02905" rpy="1.5555677 0.5106272 1.5707966"/>
      <geometry>
        <mesh filename="meshes/mesh_15.obj" scale="1. 1. 1."/>
      </geometry>
    </visual>
    <visual>
      <origin xyz="0. -0.07646 0.02905" rpy="1.6031744 0.5310113 -1.5707963"/>
      <geometry>
        <mesh filename="meshes/mesh_16.obj" scale="1. 1. 1."/>
      </geometry>
    </visual>
    <visual>
      <origin xyz="-0.364 0. 0.0735" rpy="1.5707965 0. 0. "/>
      <geometry>
        <mesh filename="meshes/mesh_17.obj" scale="1. 1. 1."/>
      </geometry>
    </visual>
    <visual>
      <origin xyz="-0.364 0. 0.1422" rpy="1.5707964 0. -1.5707964"/>
      <geometry>
        <mesh filename="meshes/mesh_18.obj" scale="1. 1. 1."/>
      </geometry>
    </visual>
    <visual>
      <origin xyz="0. 0. 0." rpy="1.5707965 0. 0. "/>
      <geometry>
        <mesh filename="meshes/mesh_19.obj" scale="1. 1. 1."/>
      </geometry>
    </visual>
    <visual>
      <origin xyz="0.2488 0.00835 0.05128" rpy="1.5707965 0. 0. "/>
      <geometry>
        <box size="0.024 0.024 0.01 "/>
      </geometry>
    </visual>
    <visual>
      <origin xyz="0.5 0.125 0.05 " rpy="0. 0. 0."/>
      <geometry>
        <sphere radius="0.05"/>
      </geometry>
    </visual>
    <visual>
      <origin xyz="-0.5 0.125 0.05 " rpy="0. 0. 0."/>
      <geometry>
        <sphere radius="0.05"/>
      </geometry>
    </visual>
    <visual>
      <origin xyz="0.5 -0.125 0.05 " rpy="0. 0. 0."/>
      <geometry>
        <sphere radius="0.05"/>
      </geometry>
    </visual>
    <visual>
      <origin xyz="-0.5 -0.125 0.05 " rpy="0. 0. 0."/>
      <geometry>
        <sphere radius="0.05"/>
      </geometry>
    </visual>
    <collision>
      <origin xyz="0.5 0.125 0.05 " rpy="0. 0. 0."/>
      <geometry>
        <sphere radius="0.05"/>
      </geometry>
    </collision>
    <collision>
      <origin xyz="-0.5 0.125 0.05 " rpy="0. 0. 0."/>
      <geometry>
        <sphere radius="0.05"/>
      </geometry>
    </collision>
    <collision>
      <origin xyz="0.5 -0.125 0.05 " rpy="0. 0. 0."/>
      <geometry>
        <sphere radius="0.05"/>
      </geometry>
    </collision>
    <collision>
      <origin xyz="-0.5 -0.125 0.05 " rpy="0. 0. 0."/>
      <geometry>
        <sphere radius="0.05"/>
      </geometry>
    </collision>
  </link>
</robot>
